<?xml version="1.0"?>

<robot name="delivery_bot">

  <!-- ================= MATERIALS ================= -->

  <material name="black">
    <color rgba="0 0 0 1"/>
  </material>

  <material name="blue">
    <color rgba="0 0 1 1"/>
  </material>

  <material name="red">
    <color rgba="1 0 0 1"/>
  </material>

  <!-- ================= BASE FOOTPRINT ================= -->

  <link name="base_footprint"/>

  <!-- ================= BASE LINK ================= -->

  <link name="base_link">

    <visual>
      <origin xyz="0 0 0.05" rpy="0 0 0"/>
      <geometry>
        <box size="0.4 0.3 0.1"/>
      </geometry>
      <material name="blue"/>
    </visual>

    <collision>
      <origin xyz="0 0 0.05" rpy="0 0 0"/>
      <geometry>
        <box size="0.4 0.3 0.1"/>
      </geometry>
    </collision>

    <inertial>
      <origin xyz="0 0 0.05" rpy="0 0 0"/>
      <mass value="5.0"/>

      <inertia
        ixx="0.1"
        iyy="0.1"
        izz="0.1"
        ixy="0.0"
        ixz="0.0"
        iyz="0.0"/>
    </inertial>

  </link>

  <!-- ================= BASE JOINT ================= -->

  <joint name="base_joint" type="fixed">
    <parent link="base_footprint"/>
    <child link="base_link"/>
    <origin xyz="0 0 0" rpy="0 0 0"/>
  </joint>

  <!-- ================= LEFT WHEEL ================= -->

  <link name="left_wheel">

    <visual>
      <origin xyz="0 0 0" rpy="1.5707 0 0"/>
      <geometry>
        <cylinder radius="0.07" length="0.05"/>
      </geometry>
      <material name="black"/>
    </visual>

    <collision>
      <origin xyz="0 0 0" rpy="1.5707 0 0"/>
      <geometry>
        <cylinder radius="0.07" length="0.05"/>
      </geometry>
    </collision>

    <inertial>
      <mass value="1.0"/>
      <inertia
        ixx="0.02"
        iyy="0.02"
        izz="0.02"
        ixy="0"
        ixz="0"
        iyz="0"/>
    </inertial>

  </link>

  <!-- ================= RIGHT WHEEL ================= -->

  <link name="right_wheel">

    <visual>
       <origin xyz="0 0 0" rpy="1.5707 0 0"/>
      <geometry>
        <cylinder radius="0.07" length="0.05"/>
      </geometry>
      <material name="black"/>
    </visual>

    <collision>
       <origin xyz="0 0 0" rpy="1.5707 0 0"/>
      <geometry>
        <cylinder radius="0.07" length="0.05"/>
      </geometry>
    </collision>

    <inertial>
      <mass value="1.0"/>
      <inertia
        ixx="0.02"
        iyy="0.02"
        izz="0.02"
        ixy="0"
        ixz="0"
        iyz="0"/>
    </inertial>

  </link>

  <!-- ================= WHEEL JOINTS ================= -->

  <joint name="left_wheel_joint" type="continuous">
    <parent link="base_link"/>
    <child link="left_wheel"/>
    <origin xyz="0 0.15 0.07" rpy="0 0 0"/>
    <axis xyz="0 0 1"/>
  </joint>

  <joint name="right_wheel_joint" type="continuous">
    <parent link="base_link"/>
    <child link="right_wheel"/>
    <origin xyz="0 -0.15 0.07" rpy="0 0 0"/>
    <axis xyz="0 0 1"/>
  </joint>

  <!-- ================= CASTER ================= -->

  <link name="caster_wheel">

    <visual>
      <geometry>
        <sphere radius="0.03"/>
      </geometry>
      <material name="black"/>
    </visual>

    <collision>
      <geometry>
        <sphere radius="0.03"/>
      </geometry>
    </collision>

    <inertial>
      <mass value="0.2"/>
      <inertia
        ixx="0.001"
        iyy="0.001"
        izz="0.001"
        ixy="0"
        ixz="0"
        iyz="0"/>
    </inertial>

  </link>

  <joint name="caster_joint" type="fixed">
    <parent link="base_link"/>
    <child link="caster_wheel"/>
    <origin xyz="-0.15 0 -0.03"/>
  </joint>

  <!-- ================= LIDAR ================= -->

  <link name="lidar_link">

    <visual>
      <geometry>
        <cylinder radius="0.05" length="0.05"/>
      </geometry>
      <material name="red"/>
    </visual>

    <collision>
      <geometry>
        <cylinder radius="0.05" length="0.05"/>
      </geometry>
    </collision>

    <inertial>
      <mass value="0.1"/>
      <inertia
        ixx="0.001"
        iyy="0.001"
        izz="0.001"
        ixy="0"
        ixz="0"
        iyz="0"/>
    </inertial>

  </link>

  <joint name="lidar_joint" type="fixed">
    <parent link="base_link"/>
    <child link="lidar_link"/>
    <origin xyz="0 0 0.15" rpy="0 0 0"/>
  </joint>

  <!-- ================= GAZEBO COLORS ================= -->

  <gazebo reference="base_link">
    <material>Gazebo/Blue</material>
  </gazebo>

  <gazebo reference="left_wheel">
    <material>Gazebo/Black</material>
    <mu1>100.0</mu1>
    <mu2>100.0</mu2>
  </gazebo>

  <gazebo reference="right_wheel">
    <material>Gazebo/Black</material>
    <mu1>100.0</mu1>
    <mu2>100.0</mu2>
  </gazebo>

  <gazebo reference="lidar_link">
    <material>Gazebo/Red</material>
  </gazebo>

  <!-- ================= LIDAR SENSOR ================= -->

  <gazebo reference="lidar_link">

    <sensor name="lidar" type="ray">

      <update_rate>10</update_rate>

      <ray>

        <scan>
          <horizontal>
            <samples>360</samples>
            <min_angle>-3.14</min_angle>
            <max_angle>3.14</max_angle>
          </horizontal>
        </scan>

        <range>
          <min>0.1</min>
          <max>10.0</max>
        </range>

      </ray>

      <plugin
        name="gazebo_ros_laser"
        filename="libgazebo_ros_ray_sensor.so">

        <ros>
          <remapping>~/out:=scan</remapping>
        </ros>

        <output_type>sensor_msgs/LaserScan</output_type>
        <frame_name>lidar_link</frame_name>

      </plugin>

    </sensor>

  </gazebo>

  <!-- ================= DIFF DRIVE ================= -->

  <gazebo>

    <plugin
      name="diff_drive"
      filename="libgazebo_ros_diff_drive.so">

      <left_joint>left_wheel_joint</left_joint>
      <right_joint>right_wheel_joint</right_joint>

      <wheel_separation>0.30</wheel_separation>
      <wheel_diameter>0.14</wheel_diameter>

      <cmd_vel_topic>cmd_vel</cmd_vel_topic>
      <odom_topic>odom</odom_topic>

      <publish_odom>true</publish_odom>
      <publish_odom_tf>true</publish_odom_tf>

    </plugin>

  </gazebo>

</robot>
